<sdf version='1.7'>
<world name='default'>
<model name="robot_dog">
      <link name="base_link">
        <pose relative_to='__model__'>0 -0.5 0.25 0 0 0</pose>
        <visual name="visual">
          <geometry>
            <box>
              <size>0.4 0.3 0.1</size>
            </box>
          </geometry>
          <material>
            <ambient> 1.0 0.0 0.0 1</ambient>
            <diffuse> 1.0 0.0 0.0 1</diffuse>
            <specular> 1.0 0.0 0.0 1</specular>
          </material>
        </visual>
        <collision name="collision">
          <geometry>
            <box>
              <size>0.4 0.3 0.1</size>
            </box>
          </geometry>
        </collision>
      </link>
      <link name="left_front_leg">
        <pose relative_to='base_link'>-0.15 -0.1 -0.1 0 0 0</pose>
        <visual name="visual">
          <geometry>
            <cylinder>
              <length>0.2</length>
              <radius>0.05</radius>
            </cylinder>
          </geometry>
          <material>
            <ambient> 1.0 0.0 0.0 1</ambient>
            <diffuse> 1.0 0.0 0.0 1</diffuse>
            <specular> 1.0 0.0 0.0 1</specular>
          </material>
        </visual>
        <collision name="collision">
          <geometry>
            <cylinder>
              <length>0.2</length>
              <radius>0.05</radius>
            </cylinder>
          </geometry>
        </collision>
      </link>
      <link name="left_front_wheel">
        <pose relative_to='left_front_leg'>0 0 -0.1 0 0 0</pose>
        <visual name="visual">
          <geometry>
            <sphere>
              <radius>0.05</radius>
            </sphere>
          </geometry>
          <material>
            <ambient> 0.0 0.0 1.0 1</ambient>
            <diffuse> 0.0 0.0 1.0 1</diffuse>
            <specular> 0.0 0.0 1.0 1</specular>
          </material>
        </visual>
        <collision name="collision">
          <geometry>
            <sphere>
              <radius>0.05</radius>
            </sphere>
          </geometry>
        </collision>
      </link>
      <link name="right_front_leg">
        <pose relative_to='base_link'>-0.15 0.1 -0.1 0 0 0</pose>
        <visual name="visual">
          <geometry>
            <cylinder>
              <length>0.2</length>
              <radius>0.05</radius>
            </cylinder>
          </geometry>
          <material>
            <ambient> 1.0 0.0 0.0 1</ambient>
            <diffuse> 1.0 0.0 0.0 1</diffuse>
            <specular> 1.0 0.0 0.0 1</specular>
          </material>
        </visual>
        <collision name="collision">
          <geometry>
            <cylinder>
              <length>0.2</length>
              <radius>0.05</radius>
            </cylinder>
          </geometry>
        </collision>
      </link>
      <link name="right_front_wheel">
        <pose relative_to='right_front_leg'>0 0 -0.1 0 0 0</pose>
        <visual name="visual">
          <geometry>
            <sphere>
              <radius>0.05</radius>
            </sphere>
          </geometry>
          <material>
            <ambient> 0.0 0.0 1.0 1</ambient>
            <diffuse> 0.0 0.0 1.0 1</diffuse>
            <specular> 0.0 0.0 1.0 1</specular>
          </material>
        </visual>
        <collision name="collision">
          <geometry>
            <sphere>
              <radius>0.05</radius>
            </sphere>
          </geometry>
        </collision>
      </link>
      <link name="neck">
        <pose relative_to='base_link'>-0.15 0 0.115 0 0 0</pose>
        <visual name="visual">
          <geometry>
            <cylinder>
              <length>0.13</length>
              <radius>0.05</radius>
            </cylinder>
          </geometry>
          <material>
            <ambient> 1.0 0.0 0.0 1</ambient>
            <diffuse> 1.0 0.0 0.0 1</diffuse>
            <specular> 1.0 0.0 0.0 1</specular>
          </material>
        </visual>
        <collision name="collision">
          <geometry>
            <cylinder>
              <length>0.13</length>
              <radius>0.05</radius>
            </cylinder>
          </geometry>
        </collision>
      </link>
      <link name="head">
        <pose relative_to='neck'>-0.02 0 0.06 0 0 0</pose>
        <visual name="visual">
          <geometry>
            <sphere>
              <radius>0.08</radius>
            </sphere>
          </geometry>
          <material>
            <ambient> 1.0 0.0 0.0 1</ambient>
            <diffuse> 1.0 0.0 0.0 1</diffuse>
            <specular> 1.0 0.0 0.0 1</specular>
          </material>
        </visual>
        <collision name="collision">
          <geometry>
            <sphere>
              <radius>0.08</radius>
            </sphere>
          </geometry>
        </collision>
      </link>
      <link name="left_ear">
        <pose relative_to='head'>0.02 -0.04 0.05 0 0 0</pose>
        <visual name="visual">
          <geometry>
            <sphere>
              <radius>0.05</radius>
            </sphere>
          </geometry>
          <material>
            <ambient> 1.0 0.0 0.0 1</ambient>
            <diffuse> 1.0 0.0 0.0 1</diffuse>
            <specular> 1.0 0.0 0.0 1</specular>
          </material>
        </visual>
        <collision name="collision">
          <geometry>
            <sphere>
              <radius>0.05</radius>
            </sphere>
          </geometry>
        </collision>
      </link>
      <link name="right_ear">
        <pose relative_to='head'>0.02 0.04 0.05 0 0 0</pose>
        <visual name="visual">
          <geometry>
            <sphere>
              <radius>0.05</radius>
            </sphere>
          </geometry>
          <material>
            <ambient> 1.0 0.0 0.0 1</ambient>
            <diffuse> 1.0 0.0 0.0 1</diffuse>
            <specular> 1.0 0.0 0.0 1</specular>
          </material>
        </visual>
        <collision name="collision">
          <geometry>
            <sphere>
              <radius>0.05</radius>
            </sphere>
          </geometry>
        </collision>
      </link>
      <link name="left_back_leg">
        <pose relative_to='base_link'>0.15 -0.1 -0.1 0 0 0</pose>
        <visual name="visual">
          <geometry>
            <cylinder>
              <length>0.2</length>
              <radius>0.05</radius>
            </cylinder>
          </geometry>
          <material>
            <ambient> 1.0 0.0 0.0 1</ambient>
            <diffuse> 1.0 0.0 0.0 1</diffuse>
            <specular> 1.0 0.0 0.0 1</specular>
          </material>
        </visual>
        <collision name="collision">
          <geometry>
            <cylinder>
              <length>0.2</length>
              <radius>0.05</radius>
            </cylinder>
          </geometry>
        </collision>
      </link>
      <link name="left_back_wheel">
        <pose relative_to='left_back_leg'>0 0 -0.1 0 0 0</pose>
        <visual name="visual">
          <geometry>
            <sphere>
              <radius>0.05</radius>
            </sphere>
          </geometry>
          <material>
            <ambient> 0.0 0.0 1.0 1</ambient>
            <diffuse> 0.0 0.0 1.0 1</diffuse>
            <specular> 0.0 0.0 1.0 1</specular>
          </material>
        </visual>
        <collision name="collision">
          <geometry>
            <sphere>
              <radius>0.05</radius>
            </sphere>
          </geometry>
        </collision>
      </link>
      <link name="right_back_leg">
        <pose relative_to='base_link'>0.15 0.1 -0.1 0 0 0</pose>
        <visual name="visual">
          <geometry>
            <cylinder>
              <length>0.2</length>
              <radius>0.05</radius>
            </cylinder>
          </geometry>
          <material>
            <ambient> 1.0 0.0 0.0 1</ambient>
            <diffuse> 1.0 0.0 0.0 1</diffuse>
            <specular> 1.0 0.0 0.0 1</specular>
          </material>
        </visual>
        <collision name="collision">
          <geometry>
            <cylinder>
              <length>0.2</length>
              <radius>0.05</radius>
            </cylinder>
          </geometry>
        </collision>
      </link>
      <link name="right_back_wheel">
        <pose relative_to='right_back_leg'>0 0 -0.1 0 0 0</pose>
        <visual name="visual">
          <geometry>
            <sphere>
              <radius>0.05</radius>
            </sphere>
          </geometry>
          <material>
            <ambient> 0.0 0.0 1.0 1</ambient>
            <diffuse> 0.0 0.0 1.0 1</diffuse>
            <specular> 0.0 0.0 1.0 1</specular>
          </material>
          <origin rpy="0 0 0" xyz="0 0 0"/>
        </visual>
        <collision name="collision">
          <geometry>
            <sphere>
              <radius>0.05</radius>
            </sphere>
          </geometry>
        </collision>
      </link>
      <link name="tail">
        <pose relative_to='base_link'>0 0 0.1 0 0 0</pose>
        <visual name="visual">
          <geometry>
            <cylinder>
              <length>0.15</length>
              <radius>0.03</radius>
            </cylinder>
          </geometry>
          <material>
            <ambient> 0.0 0.0 1.0 1</ambient>
            <diffuse> 0.0 0.0 1.0 1</diffuse>
            <specular> 0.0 0.0 1.0 1</specular>
          </material>
        </visual>
        <collision name="collision">
          <geometry>
            <cylinder>
              <length>0.15</length>
              <radius>0.03</radius>
            </cylinder>
          </geometry>
        </collision>
      </link>
      <joint name="body_to_left_front_leg" type="fixed">
        <parent>base_link</parent>
        <child>left_front_leg</child>
      </joint>
      <joint name="left_front_leg_to_wheel" type="universal">
        <parent>left_front_leg</parent>
        <child>left_front_wheel</child>
        <axis>
            <xyz expressed_in='__model__'>1 0 0</xyz>
            <limit>
                <lower>-1.79769e+308</lower>    <!--negative infinity-->
                <upper>1.79769e+308</upper>     <!--positive infinity-->
            </limit>
        </axis>
        <axis2>
            <xyz expressed_in='__model__'>0 1 0</xyz>
            <limit>
                <lower>-1.79769e+308</lower>    <!--negative infinity-->
                <upper>1.79769e+308</upper>     <!--positive infinity-->
            </limit>
        </axis2>
      </joint>
      <joint name="body_to_right_front_leg" type="fixed">
        <parent>base_link</parent>
        <child>right_front_leg</child>
      </joint>
      <joint name="right_front_leg_to_wheel" type="universal">
        <parent>right_front_leg</parent>
        <child>right_front_wheel</child>
        <axis>
            <xyz expressed_in='__model__'>1 0 0</xyz>
            <limit>
                <lower>-1.79769e+308</lower>    <!--negative infinity-->
                <upper>1.79769e+308</upper>     <!--positive infinity-->
            </limit>
        </axis>
        <axis2>
            <xyz expressed_in='__model__'>0 1 0</xyz>
            <limit>
                <lower>-1.79769e+308</lower>    <!--negative infinity-->
                <upper>1.79769e+308</upper>     <!--positive infinity-->
            </limit>
        </axis2>
      </joint>
      <joint name="body_to_neck" type="fixed">
        <parent>base_link</parent>
        <child>neck</child>
      </joint>
      <joint name="neck_to_head" type="revolute">
        <parent>neck</parent>
        <child>head</child>
        <axis>
            <xyz expressed_in='__model__'>0 1 0</xyz>
            <limit>
                <lower>-1.79769e+308</lower>    <!--negative infinity-->
                <upper>1.79769e+308</upper>     <!--positive infinity-->
            </limit>
        </axis>
      </joint>
      <joint name="head_to_left_ear" type="fixed">
        <parent>head</parent>
        <child>left_ear</child>
      </joint>
      <joint name="head_to_right_ear" type="fixed">
        <parent>head</parent>
        <child>right_ear</child>
      </joint>
      <joint name="body_to_left_back_leg" type="fixed">
        <parent>base_link</parent>
        <child>left_back_leg</child>
      </joint>
      <joint name="left_back_leg_to_wheel" type="universal">
        <parent>left_back_leg</parent>
        <child>left_back_wheel</child>
        <axis>
            <xyz expressed_in='__model__'>1 0 0</xyz>
            <limit>
                <lower>-1.79769e+308</lower>    <!--negative infinity-->
                <upper>1.79769e+308</upper>     <!--positive infinity-->
            </limit>
        </axis>
        <axis2>
            <xyz expressed_in='__model__'>0 1 0</xyz>
            <limit>
                <lower>-1.79769e+308</lower>    <!--negative infinity-->
                <upper>1.79769e+308</upper>     <!--positive infinity-->
            </limit>
        </axis2>
      </joint>
      <joint name="body_to_right_back_leg" type="fixed">
        <parent>base_link</parent>
        <child>right_back_leg</child>
      </joint>
      <joint name="right_back_leg_to_wheel" type="universal">
        <parent>right_back_leg</parent>
        <child>right_back_wheel</child>
        <axis>
            <xyz expressed_in='__model__'>1 0 0</xyz>
            <limit>
                <lower>-1.79769e+308</lower>    <!--negative infinity-->
                <upper>1.79769e+308</upper>     <!--positive infinity-->
            </limit>
        </axis>
        <axis2>
            <xyz expressed_in='__model__'>0 1 0</xyz>
            <limit>
                <lower>-1.79769e+308</lower>    <!--negative infinity-->
                <upper>1.79769e+308</upper>     <!--positive infinity-->
            </limit>
        </axis2>
      </joint>
      <joint name="body_to_tail" type="revolute">
        <parent>base_link</parent>
        <child>tail</child>
        <axis>
            <xyz expressed_in='__model__'>1 0 0</xyz>
            <limit>
                <lower>-1.79769e+308</lower>    <!--negative infinity-->
                <upper>1.79769e+308</upper>     <!--positive infinity-->
            </limit>
        </axis>
        <origin rpy="0 0 0" xyz="0.3 0 0"/>
      </joint>
    </model>
  </world>
  </sdf>