<sdf version='1.7'>
<world name='default'>
<model name="robot_dog">
      <link name="base_link">
        <pose relative_to='__model__'>0 -0.5 0.25 0 0 0</pose>
        <visual name="visual">
          <geometry>
            <box>
              <size>0.4 0.3 0.1</size>
            </box>
          </geometry>
          <material>
            <ambient> 1.0 0.0 0.0 1</ambient>
            <diffuse> 1.0 0.0 0.0 1</diffuse>
            <specular> 1.0 0.0 0.0 1</specular>
          </material>
        </visual>
        <collision name="collision">
          <geometry>
            <box>
              <size>0.4 0.3 0.1</size>
            </box>
          </geometry>
        </collision>
      </link>
      <!--INSERT-->
      <link name="imu_link">
        <sensor name="tb3_imu" type="imu">
          <always_on>true</always_on>
          <update_rate>200</update_rate>
          <imu>
            <angular_velocity>
              <x>
                <noise type="gaussian">
                  <mean>0.0</mean>
                  <stddev>2e-4</stddev>
                </noise>
              </x>
              <y>
                <noise type="gaussian">
                  <mean>0.0</mean>
                  <stddev>2e-4</stddev>
                </noise>
              </y>
              <z>
                <noise type="gaussian">
                  <mean>0.0</mean>
                  <stddev>2e-4</stddev>
                </noise>
              </z>
            </angular_velocity>
            <linear_acceleration>
              <x>
                <noise type="gaussian">
                  <mean>0.0</mean>
                  <stddev>1.7e-2</stddev>
                </noise>
              </x>
              <y>
                <noise type="gaussian">
                  <mean>0.0</mean>
                  <stddev>1.7e-2</stddev>
                </noise>
              </y>
              <z>
                <noise type="gaussian">
                  <mean>0.0</mean>
                  <stddev>1.7e-2</stddev>
                </noise>
              </z>
            </linear_acceleration>
          </imu>
          <plugin name="turtlebot3_imu" filename="libgazebo_ros_imu_sensor.so">
            <initial_orientation_as_reference>false</initial_orientation_as_reference>
            <ros>
              <!-- <namespace>/tb3</namespace> -->
              <remapping>~/out:=imu</remapping>
            </ros>
          </plugin>
        </sensor>
      </link>

      <link name="base_scan">
        <inertial>
          <pose relative_to='base_link'>-0.2 0 0 0 0 0</pose>
          <inertia>
            <ixx>0.001</ixx>
            <ixy>0.000</ixy>
            <ixz>0.000</ixz>
            <iyy>0.001</iyy>
            <iyz>0.000</iyz>
            <izz>0.001</izz>
          </inertia>
          <mass>0.125</mass>
        </inertial>

        <collision name="lidar_sensor_collision">
          <pose relative_to='base_link'>-0.2 0 0 0 0 0</pose>
          <geometry>
            <cylinder>
              <radius>0.0508</radius>
              <length>0.055</length>
            </cylinder>
          </geometry>
        </collision>

        <visual name="lidar_sensor_visual">
          <pose relative_to='base_link'>-0.2 0 0 0 0 0</pose>
          <geometry>
            <cylinder>
              <radius>0.0508</radius>
              <length>0.055</length>
            </cylinder>
          </geometry>
        </visual>

        <sensor name="hls_lfcd_lds" type="ray">
          <always_on>true</always_on>
          <visualize>true</visualize>
          <pose relative_to='lidar_sensor_visual'>-0.064 0 0.15 0 0 0</pose>
          <update_rate>5</update_rate>
          <ray>
            <scan>
              <horizontal>
                <samples>360</samples>
                <resolution>1.000000</resolution>
                <min_angle>0.000000</min_angle>
                <max_angle>6.280000</max_angle>
              </horizontal>
            </scan>
            <range>
              <min>0.120000</min>
              <max>20.0</max>
              <resolution>0.015000</resolution>
            </range>
            <noise>
              <type>gaussian</type>
              <mean>0.0</mean>
              <stddev>0.01</stddev>
            </noise>
          </ray>
          <plugin name="turtlebot3_laserscan" filename="libgazebo_ros_ray_sensor.so">
            <ros>
                <remapping>~/out:=scan</remapping>
            </ros>
            <output_type>sensor_msgs/LaserScan</output_type>
            <frame_name>base_scan</frame_name>
          </plugin>
        </sensor>
      </link>
      <!--INSERT Done-->
      <link name="left_front_leg">
        <pose relative_to='base_link'>-0.15 -0.1 -0.1 0 0 0</pose>
        <visual name="visual">
          <geometry>
            <cylinder>
              <length>0.2</length>
              <radius>0.05</radius>
            </cylinder>
          </geometry>
          <material>
            <ambient> 1.0 0.0 0.0 1</ambient>
            <diffuse> 1.0 0.0 0.0 1</diffuse>
            <specular> 1.0 0.0 0.0 1</specular>
          </material>
        </visual>
        <collision name="collision">
          <geometry>
            <cylinder>
              <length>0.2</length>
              <radius>0.05</radius>
            </cylinder>
          </geometry>
        </collision>
      </link>
      <link name="left_front_wheel">
        <pose relative_to='left_front_leg'>0 0 -0.1 0 0 0</pose>
        <visual name="visual">
          <geometry>
            <sphere>
              <radius>0.05</radius>
            </sphere>
          </geometry>
          <material>
            <ambient> 0.0 0.0 1.0 1</ambient>
            <diffuse> 0.0 0.0 1.0 1</diffuse>
            <specular> 0.0 0.0 1.0 1</specular>
          </material>
        </visual>
        <collision name="collision">
          <geometry>
            <sphere>
              <radius>0.05</radius>
            </sphere>
          </geometry>
        </collision>
      </link>
      <link name="right_front_leg">
        <pose relative_to='base_link'>-0.15 0.1 -0.1 0 0 0</pose>
        <visual name="visual">
          <geometry>
            <cylinder>
              <length>0.2</length>
              <radius>0.05</radius>
            </cylinder>
          </geometry>
          <material>
            <ambient> 1.0 0.0 0.0 1</ambient>
            <diffuse> 1.0 0.0 0.0 1</diffuse>
            <specular> 1.0 0.0 0.0 1</specular>
          </material>
        </visual>
        <collision name="collision">
          <geometry>
            <cylinder>
              <length>0.2</length>
              <radius>0.05</radius>
            </cylinder>
          </geometry>
        </collision>
      </link>
      <link name="right_front_wheel">
        <pose relative_to='right_front_leg'>0 0 -0.1 0 0 0</pose>
        <visual name="visual">
          <geometry>
            <sphere>
              <radius>0.05</radius>
            </sphere>
          </geometry>
          <material>
            <ambient> 0.0 0.0 1.0 1</ambient>
            <diffuse> 0.0 0.0 1.0 1</diffuse>
            <specular> 0.0 0.0 1.0 1</specular>
          </material>
        </visual>
        <collision name="collision">
          <geometry>
            <sphere>
              <radius>0.05</radius>
            </sphere>
          </geometry>
        </collision>
      </link>
      <link name="neck">
        <pose relative_to='base_link'>-0.15 0 0.115 0 0 0</pose>
        <visual name="visual">
          <geometry>
            <cylinder>
              <length>0.13</length>
              <radius>0.05</radius>
            </cylinder>
          </geometry>
          <material>
            <ambient> 1.0 0.0 0.0 1</ambient>
            <diffuse> 1.0 0.0 0.0 1</diffuse>
            <specular> 1.0 0.0 0.0 1</specular>
          </material>
        </visual>
        <collision name="collision">
          <geometry>
            <cylinder>
              <length>0.13</length>
              <radius>0.05</radius>
            </cylinder>
          </geometry>
        </collision>
      </link>
      <link name="head">
        <pose relative_to='neck'>-0.02 0 0.06 0 0 0</pose>
        <visual name="visual">
          <geometry>
            <sphere>
              <radius>0.08</radius>
            </sphere>
          </geometry>
          <material>
            <ambient> 1.0 0.0 0.0 1</ambient>
            <diffuse> 1.0 0.0 0.0 1</diffuse>
            <specular> 1.0 0.0 0.0 1</specular>
          </material>
        </visual>
        <collision name="collision">
          <geometry>
            <sphere>
              <radius>0.08</radius>
            </sphere>
          </geometry>
        </collision>
      </link>
      <link name="left_ear">
        <pose relative_to='head'>0.02 -0.04 0.05 0 0 0</pose>
        <visual name="visual">
          <geometry>
            <sphere>
              <radius>0.05</radius>
            </sphere>
          </geometry>
          <material>
            <ambient> 1.0 0.0 0.0 1</ambient>
            <diffuse> 1.0 0.0 0.0 1</diffuse>
            <specular> 1.0 0.0 0.0 1</specular>
          </material>
        </visual>
        <collision name="collision">
          <geometry>
            <sphere>
              <radius>0.05</radius>
            </sphere>
          </geometry>
        </collision>
      </link>
      <link name="right_ear">
        <pose relative_to='head'>0.02 0.04 0.05 0 0 0</pose>
        <visual name="visual">
          <geometry>
            <sphere>
              <radius>0.05</radius>
            </sphere>
          </geometry>
          <material>
            <ambient> 1.0 0.0 0.0 1</ambient>
            <diffuse> 1.0 0.0 0.0 1</diffuse>
            <specular> 1.0 0.0 0.0 1</specular>
          </material>
        </visual>
        <collision name="collision">
          <geometry>
            <sphere>
              <radius>0.05</radius>
            </sphere>
          </geometry>
        </collision>
      </link>
      <link name="left_back_leg">
        <pose relative_to='base_link'>0.15 -0.1 -0.1 0 0 0</pose>
        <visual name="visual">
          <geometry>
            <cylinder>
              <length>0.2</length>
              <radius>0.05</radius>
            </cylinder>
          </geometry>
          <material>
            <ambient> 1.0 0.0 0.0 1</ambient>
            <diffuse> 1.0 0.0 0.0 1</diffuse>
            <specular> 1.0 0.0 0.0 1</specular>
          </material>
        </visual>
        <collision name="collision">
          <geometry>
            <cylinder>
              <length>0.2</length>
              <radius>0.05</radius>
            </cylinder>
          </geometry>
        </collision>
      </link>
      <link name="left_back_wheel">
        <pose relative_to='left_back_leg'>0 0 -0.1 0 0 0</pose>
        <visual name="visual">
          <geometry>
            <sphere>
              <radius>0.05</radius>
            </sphere>
          </geometry>
          <material>
            <ambient> 0.0 0.0 1.0 1</ambient>
            <diffuse> 0.0 0.0 1.0 1</diffuse>
            <specular> 0.0 0.0 1.0 1</specular>
          </material>
        </visual>
        <collision name="collision">
          <geometry>
            <sphere>
              <radius>0.05</radius>
            </sphere>
          </geometry>
        </collision>
      </link>
      <link name="right_back_leg">
        <pose relative_to='base_link'>0.15 0.1 -0.1 0 0 0</pose>
        <visual name="visual">
          <geometry>
            <cylinder>
              <length>0.2</length>
              <radius>0.05</radius>
            </cylinder>
          </geometry>
          <material>
            <ambient> 1.0 0.0 0.0 1</ambient>
            <diffuse> 1.0 0.0 0.0 1</diffuse>
            <specular> 1.0 0.0 0.0 1</specular>
          </material>
        </visual>
        <collision name="collision">
          <geometry>
            <cylinder>
              <length>0.2</length>
              <radius>0.05</radius>
            </cylinder>
          </geometry>
        </collision>
      </link>
      <link name="right_back_wheel">
        <pose relative_to='right_back_leg'>0 0 -0.1 0 0 0</pose>
        <visual name="visual">
          <geometry>
            <sphere>
              <radius>0.05</radius>
            </sphere>
          </geometry>
          <material>
            <ambient> 0.0 0.0 1.0 1</ambient>
            <diffuse> 0.0 0.0 1.0 1</diffuse>
            <specular> 0.0 0.0 1.0 1</specular>
          </material>
          <origin rpy="0 0 0" xyz="0 0 0"/>
        </visual>
        <collision name="collision">
          <geometry>
            <sphere>
              <radius>0.05</radius>
            </sphere>
          </geometry>
        </collision>
      </link>
      <link name="tail">
        <pose relative_to='base_link'>0 0 0.1 0 0 0</pose>
        <visual name="visual">
          <geometry>
            <cylinder>
              <length>0.15</length>
              <radius>0.03</radius>
            </cylinder>
          </geometry>
          <material>
            <ambient> 0.0 0.0 1.0 1</ambient>
            <diffuse> 0.0 0.0 1.0 1</diffuse>
            <specular> 0.0 0.0 1.0 1</specular>
          </material>
        </visual>
        <collision name="collision">
          <geometry>
            <cylinder>
              <length>0.15</length>
              <radius>0.03</radius>
            </cylinder>
          </geometry>
        </collision>
      </link>
      <joint name="body_to_left_front_leg" type="fixed">
        <parent>base_link</parent>
        <child>left_front_leg</child>
      </joint>
      <joint name="left_front_leg_to_wheel" type="universal">
        <parent>left_front_leg</parent>
        <child>left_front_wheel</child>
        <axis>
            <xyz expressed_in='__model__'>1 0 0</xyz>
            <limit>
                <lower>-1.79769e+308</lower>    <!--negative infinity-->
                <upper>1.79769e+308</upper>     <!--positive infinity-->
            </limit>
        </axis>
        <axis2>
            <xyz expressed_in='__model__'>0 1 0</xyz>
            <limit>
                <lower>-1.79769e+308</lower>    <!--negative infinity-->
                <upper>1.79769e+308</upper>     <!--positive infinity-->
            </limit>
        </axis2>
      </joint>
      <joint name="body_to_right_front_leg" type="fixed">
        <parent>base_link</parent>
        <child>right_front_leg</child>
      </joint>
      <joint name="right_front_leg_to_wheel" type="universal">
        <parent>right_front_leg</parent>
        <child>right_front_wheel</child>
        <axis>
            <xyz expressed_in='__model__'>1 0 0</xyz>
            <limit>
                <lower>-1.79769e+308</lower>    <!--negative infinity-->
                <upper>1.79769e+308</upper>     <!--positive infinity-->
            </limit>
        </axis>
        <axis2>
            <xyz expressed_in='__model__'>0 1 0</xyz>
            <limit>
                <lower>-1.79769e+308</lower>    <!--negative infinity-->
                <upper>1.79769e+308</upper>     <!--positive infinity-->
            </limit>
        </axis2>
      </joint>
      <joint name="body_to_neck" type="fixed">
        <parent>base_link</parent>
        <child>neck</child>
      </joint>
      <joint name="neck_to_head" type="revolute">
        <parent>neck</parent>
        <child>head</child>
        <axis>
            <xyz expressed_in='__model__'>0 1 0</xyz>
            <limit>
                <lower>-1.79769e+308</lower>    <!--negative infinity-->
                <upper>1.79769e+308</upper>     <!--positive infinity-->
            </limit>
        </axis>
      </joint>
      <joint name="head_to_left_ear" type="fixed">
        <parent>head</parent>
        <child>left_ear</child>
      </joint>
      <joint name="head_to_right_ear" type="fixed">
        <parent>head</parent>
        <child>right_ear</child>
      </joint>
      <joint name="body_to_left_back_leg" type="fixed">
        <parent>base_link</parent>
        <child>left_back_leg</child>
      </joint>
      <joint name="left_back_leg_to_wheel" type="universal">
        <parent>left_back_leg</parent>
        <child>left_back_wheel</child>
        <axis>
            <xyz expressed_in='__model__'>1 0 0</xyz>
            <limit>
                <lower>-1.79769e+308</lower>    <!--negative infinity-->
                <upper>1.79769e+308</upper>     <!--positive infinity-->
            </limit>
        </axis>
        <axis2>
            <xyz expressed_in='__model__'>0 1 0</xyz>
            <limit>
                <lower>-1.79769e+308</lower>    <!--negative infinity-->
                <upper>1.79769e+308</upper>     <!--positive infinity-->
            </limit>
        </axis2>
      </joint>
      <joint name="body_to_right_back_leg" type="fixed">
        <parent>base_link</parent>
        <child>right_back_leg</child>
      </joint>
      <joint name="right_back_leg_to_wheel" type="universal">
        <parent>right_back_leg</parent>
        <child>right_back_wheel</child>
        <axis>
            <xyz expressed_in='__model__'>1 0 0</xyz>
            <limit>
                <lower>-1.79769e+308</lower>    <!--negative infinity-->
                <upper>1.79769e+308</upper>     <!--positive infinity-->
            </limit>
        </axis>
        <axis2>
            <xyz expressed_in='__model__'>0 1 0</xyz>
            <limit>
                <lower>-1.79769e+308</lower>    <!--negative infinity-->
                <upper>1.79769e+308</upper>     <!--positive infinity-->
            </limit>
        </axis2>
      </joint>
      <joint name="body_to_tail" type="revolute">
        <parent>base_link</parent>
        <child>tail</child>
        <axis>
            <xyz expressed_in='__model__'>1 0 0</xyz>
            <limit>
                <lower>-1.79769e+308</lower>    <!--negative infinity-->
                <upper>1.79769e+308</upper>     <!--positive infinity-->
            </limit>
        </axis>
        <origin rpy="0 0 0" xyz="0.3 0 0"/>
      </joint>
      <!--gazebo module-->
      <plugin name="turtlebot3_diff_drive" filename="libgazebo_ros_diff_drive.so">

        <ros>
          <!-- <namespace>/tb3</namespace> -->
          <!--since gazebo_plugins publish tf topic in global namespace /tf only and it
            cannot be remapped like (namespace/tf) through launch arguments -->
          <remapping>/tf:=tf</remapping>
        </ros>

        <update_rate>30</update_rate>

        <!-- wheels -->
        <left_joint>left_back_leg_to_wheel</left_joint>
        <right_joint>right_back_leg_to_wheel</right_joint>

        <!-- kinematics -->
        <wheel_separation>0.3</wheel_separation>
        <wheel_diameter>0.05</wheel_diameter>

        <!-- limits -->
        <max_wheel_torque>20</max_wheel_torque>
        <max_wheel_acceleration>1.0</max_wheel_acceleration>

        <command_topic>cmd_vel</command_topic>

        <!-- output -->
        <publish_odom>true</publish_odom>
        <publish_odom_tf>true</publish_odom_tf>
        <publish_wheel_tf>false</publish_wheel_tf>

        <odometry_topic>odom</odometry_topic>
        <odometry_frame>odom</odometry_frame>
        <robot_base_frame>base_footprint</robot_base_frame>

      </plugin>

      <plugin name="turtlebot3_joint_state" filename="libgazebo_ros_joint_state_publisher.so">
        <ros>
          <!-- <namespace>/tb3</namespace> -->
            <remapping>~/out:=joint_states</remapping>
        </ros>
        <update_rate>30</update_rate>
        <joint_name>left_back_leg_to_wheel</joint_name>
        <joint_name>right_back_leg_to_wheel</joint_name>
      </plugin>

    </model>
  </world>
  </sdf>